<!DOCTYPE html>
<html lang="en">
<head>
    <meta charset="UTF-8">
    <meta name="viewport" content="width=device-width, initial-scale=1.0">
    <title>Promise关键问题 - 异常穿透</title>
</head>
<body>
    <script>
        let p = new Promise((resolve, reject) => {
            setTimeout(() => {
                // resolve('OK');
                reject('Err');
            }, 1000);
        });

        const result = p.then(value => {
            console.log(111);
            // throw '失败啦!';
        })
        .then(value => {
            console.log(222);
        })
        .then(value => {
            console.log(333);
        }).catch(reason => {
            console.warn(reason);
        });//也可以用then 但是要有两个参数
        // 确实没讲异常穿透的原因.原因是上面一串then(所有then都只有value,而没有reason)没有处理异常,所以每个then的返回值就是上一个promise的值;所以最后catch了.

        console.log(result);
    </script>
</body>
</html>